<?xml version="1.0" encoding="utf-8"?>
<!-- This URDF was automatically created by SolidWorks to URDF Exporter! Originally created by Stephen Brawner (brawner@gmail.com) 
     Commit Version: 1.6.0-1-g15f4949  Build Version: 1.6.7594.29634
     For more information, please see http://wiki.ros.org/sw_urdf_exporter -->
<robot
  name="nezha_description">
  <link
    name="base">
    <inertial>
      <origin
        xyz="-0.00000691 -0.00000693 -0.00000186"
        rpy="0 0 0" />
      <mass
        value="37.6" />
      <inertia
        ixx="0.59007413"
        ixy="0.0026156"
        ixz="0.004971"
        iyy="1.98506693"
        iyz="0.021971"
        izz="2.344962" />
    </inertial>
    <visual>
      <origin
        xyz="0 0 0"
        rpy="0 0 0" />
      <geometry>
        <mesh
          filename="../meshes/trunk.STL" />
      </geometry>
      <material
        name="">
        <color
          rgba="0.75294 0.75294 0.75294 1" />
      </material>
    </visual>
      <collision>
        <origin xyz="0.048 -0.027 -0.045"  rpy="0 0 0" />
        <geometry>
          <box size="1.0 0.400 0.140" />
        </geometry>
      </collision>
  </link>
    <link name="imu_fixed_link">
      <inertial>
        <origin xyz="-0.00353754349894037 4.2154628186554E-05 -0.00997114982725278"  rpy="0 0 0" />
        <mass value="0.0406912140939172" />
        <inertia 
          ixx="8.58656611098232E-06"
          ixy="1.44679601180708E-09"
          ixz="3.26182945796814E-08"
          iyy="6.09072078801729E-06"
          iyz="-7.38008178299839E-11"
          izz="1.19225496991543E-05" />
      </inertial>
      <visual>
        <origin xyz="0 0 0"  rpy="0 0 0" />
        <geometry>
          <mesh filename="../meshes/imu_fixed_joint.STL" />
        </geometry>
      </visual>
    </link>
    <joint name="imu_fixed_joint" type="fixed">
      <origin xyz="0.00112019201975541 -0.0364882468746482 0.0510999999999999" rpy="0 0 0" />
      <parent link="base" />
      <child link="imu_fixed_link" />
      <axis xyz="0 0 0" />
    </joint>
  <link
    name="Lidar">
    <inertial>
      <origin
        xyz="-0.095072 0.0080005 0.014752"
        rpy="0 0 0" />
      <mass
        value="1" />
      <inertia
        ixx="0.0060381"
        ixy="2.708E-06"
        ixz="-0.00034005"
        iyy="0.0073655"
        iyz="6.2148E-07"
        izz="0.0031135" />
    </inertial>
    <visual>
      <origin
        xyz="0 0 0"
        rpy="0 0 0" />
      <geometry>
        <mesh
          filename="../meshes/Lidar.STL" />
      </geometry>
      <material
        name="">
        <color
          rgba="0.75294 0.75294 0.75294 1" />
      </material>
    </visual>
    <!--空碰撞-->
  </link>
  <joint
    name="Lidar_fixed_joint"
    type="fixed">
    <origin
      xyz="0.6019 -0.041631 0.032239"
      rpy="0 0 0" />
    <parent
      link="base" />
    <child
      link="Lidar" />
    <axis
      xyz="1 0 0" />
  </joint>
  <link
    name="FL_hip">
    <inertial>
      <origin
        xyz="-0.016427 0.0038854 2.206E-06"
        rpy="0 0 0" />
      <mass
        value="3.1" />
      <inertia
        ixx="0.00586263"
        ixy="0.00040875"
        ixz="-3.064E-05"
        iyy="0.00941998"
        iyz="2.4E-07"
        izz="0.00823554" />
    </inertial>
    <visual>
      <origin
        xyz="0 0 0"
        rpy="0 0 0" />
      <geometry>
        <mesh
          filename="../meshes/FL_hip.STL" />
      </geometry>
      <material
        name="">
        <color
          rgba="0.75294 0.75294 0.75294 1" />
      </material>
    </visual>
    <!--空碰撞-->
  </link>
  <joint
    name="FL_hip_joint"
    type="revolute">
    <origin
      xyz="0.43304 0.056588 0.00014972"
      rpy="0 0 0" />
    <parent
      link="base" />
    <child
      link="FL_hip" />
    <axis
      xyz="1 0 0" />
    <!-- <dynamics damping="0.05" friction="0.01" /> -->
    <limit
      lower="-1.31"
      upper="0.81"
      effort="150"
      velocity="12" />
  </joint>
  <link
    name="FL_thigh">
    <inertial>
      <origin
        xyz="-0.0051952 0.00015428 -0.092972"
        rpy="0 0 0" />
      <mass
        value="4.1" />
      <inertia
        ixx="0.07198856"
        ixy="-5.6758E-04"
        ixz="0.00301969"
        iyy="0.06899899"
        iyz="-0.00892753"
        izz="0.01143578" />
    </inertial>
    <visual>
      <origin
        xyz="0 0 0"
        rpy="0 0 0" />
      <geometry>
        <mesh
          filename="../meshes/FL_thigh.STL" />
      </geometry>
      <material
        name="">
        <color
          rgba="0.75294 0.75294 0.75294 1" />
      </material>
    </visual>
    <!--空碰撞-->
  </link>
  <joint
    name="FL_thigh_joint"
    type="revolute">
    <origin
      xyz="0 0.1324 0"
      rpy="0 0 0" />
    <parent
      link="FL_hip" />
    <child
      link="FL_thigh" />
    <axis
      xyz="0 1 0" />
    <!-- <dynamics damping="0.05" friction="0.01" /> -->
    <limit
      lower="-1.5"
      upper="2.6"
      effort="150"
      velocity="12" />
  </joint>
  <link
    name="FL_calf">
    <inertial>
      <origin
        xyz="-0.00045097 -0.010664 -0.14659"
        rpy="0 0 0" />
      <mass
        value="0.8" />
      <inertia
        ixx="0.01454306"
        ixy="1.8E-07"
        ixz="8.077E-05"
        iyy="0.01488481"
        iyz="-0.00016534"
        izz="0.00041348" />
    </inertial>
    <visual>
      <origin
        xyz="0 0 0"
        rpy="0 0 0" />
      <geometry>
        <mesh
          filename="../meshes/FL_calf.STL" />
      </geometry>
      <material
        name="">
        <color
          rgba="0.75294 0.75294 0.75294 1" />
      </material>
    </visual>
      <collision>
        <origin xyz="0 -0.0 -0.170" rpy="0 0 0" />
        <geometry>
          <box size="0.05 0.045 0.390" />
        </geometry>
      </collision>
  </link>
  <joint
    name="FL_calf_joint"
    type="revolute">
    <origin
      xyz="0 0.0241 -0.33"
      rpy="0 0 0" />
    <parent
      link="FL_thigh" />
    <child
      link="FL_calf" />
    <axis
      xyz="0 1 0" />
    <!-- <dynamics damping="0.05" friction="0.01" /> -->
    <limit
      lower="-2.3"
      upper="-0.52"
      effort="150"
      velocity="8" />
  </joint>
  <link
    name="FL_footmotor">
    <inertial>
      <origin
        xyz="-3.0983E-07 0.037959 0.0077964"
        rpy="0 0 0" />
      <mass
        value="1" />
      <inertia
        ixx="0.00122551"
        ixy="1.0E-08"
        ixz="8.9E-07"
        iyy="0.00121122"
        iyz="-0.00011534"
        izz="0.00111829" />
    </inertial>
    <visual>
      <origin
        xyz="0 0 0"
        rpy="0 0 0" />
      <geometry>
        <mesh
          filename="../meshes/FL_footmotor.STL" />
      </geometry>
      <material
        name="">
        <color
          rgba="0.75294 0.75294 0.75294 1" />
      </material>
    </visual>
    <!--空碰撞-->
  </link>
  <joint
    name="FL_footmotor_fixed"
    type="fixed">
    <origin
      xyz="0 -0.019084 -0.3352"
      rpy="0 0 0" />
    <parent
      link="FL_calf" />
    <child
      link="FL_footmotor" />
    <axis
      xyz="0 0 0" />
  </joint>
  <link
    name="FL_foot">
    <inertial>
      <origin
        xyz="2.5253E-10 -0.00082202 -5.8039E-08"
        rpy="0 0 0" />
      <mass
        value="0.8" />
      <inertia
        ixx="0.00322619"
        ixy="0.0"
        ixz="0.0"
        iyy="0.00620216"
        iyz="0.0"
        izz="0.00322620" />
    </inertial>
    <visual>
      <origin
        xyz="0 0 0"
        rpy="0 0 0" />
      <geometry>
        <mesh
          filename="../meshes/FL_foot.STL" />
      </geometry>
      <material
        name="">
        <color
          rgba="0.75294 0.75294 0.75294 1" />
      </material>
    </visual>
      <collision>
        <origin xyz="0 0.0 0" rpy="1.5707963267948966 0 0" />
        <geometry>
          <cylinder length="0.040" radius="0.105" />
        </geometry>
      </collision>
  </link>
  <joint
    name="FL_foot_joint"
    type="revolute">
    <origin
      xyz="0 0.067334 0.0052008"
      rpy="0 0 0" />
    <parent
      link="FL_footmotor" />
    <child
      link="FL_foot" />
    <axis
      xyz="0 1 0" />
    <!-- <dynamics friction="1.0" /> -->
    <limit
      lower="-9999"
      upper="9999"
      effort="56"
      velocity="47" />
  </joint>
  <link
    name="FR_hip">
    <inertial>
      <origin
        xyz="-0.016427 -0.0038854 -2.206E-06"
        rpy="0 0 0" />
      <mass
        value="3.1" />
      <inertia
        ixx="0.00586263"
        ixy="-0.00040875"
        ixz="3.064E-05"
        iyy="0.00941998"
        iyz="-2.4E-07"
        izz="0.00823554" />
    </inertial>
    <visual>
      <origin
        xyz="0 0 0"
        rpy="0 0 0" />
      <geometry>
        <mesh
          filename="../meshes/FR_hip.STL" />
      </geometry>
      <material
        name="">
        <color
          rgba="0.75294 0.75294 0.75294 1" />
      </material>
    </visual>
    <!--空碰撞-->
  </link>
  <joint
    name="FR_hip_joint"
    type="revolute">
    <origin
      xyz="0.43304 -0.11341 0.00014972"
      rpy="0 0 0" />
    <parent
      link="base" />
    <child
      link="FR_hip" />
    <axis
      xyz="1 0 0" />
    <!-- <dynamics damping="0.05" friction="0.01" /> -->
    <limit
      lower="-0.8"
      upper="1.3"
      effort="150"
      velocity="12" />
  </joint>
  <link
    name="FR_thigh">
    <inertial>
      <origin
        xyz="-0.0055271 -0.00015362 -0.092992"
        rpy="0 0 0" />
      <mass
        value="4.1" />
      <inertia
        ixx="0.07200998"
        ixy="0.00045575"
        ixz="0.00288100"
        iyy="0.06900584"
        iyz="0.00892980"
        izz="0.01142712" />
    </inertial>
    <visual>
      <origin
        xyz="0 0 0"
        rpy="0 0 0" />
      <geometry>
        <mesh
          filename="../meshes/FR_thigh.STL" />
      </geometry>
      <material
        name="">
        <color
          rgba="0.75294 0.75294 0.75294 1" />
      </material>
    </visual>
    <!--空碰撞-->
  </link>
  <joint
    name="FR_thigh_joint"
    type="revolute">
    <origin
      xyz="0 -0.1324 0"
      rpy="0 0 0" />
    <parent
      link="FR_hip" />
    <child
      link="FR_thigh" />
    <axis
      xyz="0 1 0" />
    <!-- <dynamics damping="0.05" friction="0.01" /> -->
    <limit
      lower="-1.6"
      upper="2.6"
      effort="150"
      velocity="12" />
  </joint>
  <link
    name="FR_calf">
    <inertial>
      <origin
        xyz="-0.00040423 -0.0007071 -0.14806"
        rpy="0 0 0" />
      <mass
        value="0.8" />
      <inertia
        ixx="0.01454129"
        ixy="-5.5E-07"
        ixz="-6.627E-05"
        iyy="0.01478402"
        iyz="9.312E-05"
        izz="0.00049281" />
    </inertial>
    <visual>
      <origin
        xyz="0 0 0"
        rpy="0 0 0" />
      <geometry>
        <mesh
          filename="../meshes/FR_calf.STL" />
      </geometry>
      <material
        name="">
        <color
          rgba="0.75294 0.75294 0.75294 1" />
      </material>
    </visual>
      <collision>
        <origin xyz="0 0.0 -0.170" rpy="0 0 0" />
        <geometry>
          <box size="0.05 0.045 0.390" />
        </geometry>
      </collision>
  </link>
  <joint
    name="FR_calf_joint"
    type="revolute">
    <origin
      xyz="0 -0.0241 -0.33"
      rpy="0 0 0" />
    <parent
      link="FR_thigh" />
    <child
      link="FR_calf" />
    <axis
      xyz="0 1 0" />
    <!-- <dynamics damping="0.05" friction="0.01" /> -->
    <limit
      lower="-2.4"
      upper="-0.57"
      effort="150"
      velocity="8" />
  </joint>
  <link
    name="FR_footmotor">
    <inertial>
      <origin
        xyz="3.0956E-07 -0.037959 0.0077964"
        rpy="0 0 0" />
      <mass
        value="1" />
      <inertia
        ixx="0.00122551"
        ixy="1.0E-08"
        ixz="-8.9E-07"
        iyy="0.00121122"
        iyz="0.00011534"
        izz="0.00111829" />
    </inertial>
    <visual>
      <origin
        xyz="0 0 0"
        rpy="0 0 0" />
      <geometry>
        <mesh
          filename="../meshes/FR_footmotor.STL" />
      </geometry>
      <material
        name="">
        <color
          rgba="0.75294 0.75294 0.75294 1" />
      </material>
    </visual>
    <!--空碰撞-->
  </link>
  <joint
    name="FR_footmotor_fixed"
    type="fixed">
    <origin
      xyz="0 0.019084 -0.3352"
      rpy="0 0 0" />
    <parent
      link="FR_calf" />
    <child
      link="FR_footmotor" />
    <axis
      xyz="0 0 0" />
  </joint>
  <link
    name="FR_foot">
    <inertial>
      <origin
        xyz="-5.5178E-08 0.00082201 1.8207E-08"
        rpy="0 0 0" />
      <mass
        value="0.8" />
      <inertia
        ixx="0.00322619"
        ixy="0.0"
        ixz="0.0"
        iyy="0.00620216"
        iyz="0.0"
        izz="0.00322620" />
    </inertial>
    <visual>
      <origin
        xyz="0 0 0"
        rpy="0 0 0" />
      <geometry>
        <mesh
          filename="../meshes/FR_foot.STL" />
      </geometry>
      <material
        name="">
        <color
          rgba="0.75294 0.75294 0.75294 1" />
      </material>
    </visual>
      <collision>
        <origin xyz="0 -0.0 0" rpy="1.5707963267948966 0 0" />
        <geometry>
          <cylinder length="0.040" radius="0.105" />
        </geometry>
      </collision>
  </link>
  <joint
    name="FR_foot_joint"
    type="revolute">
    <origin
      xyz="0 -0.067334 0.0052008"
      rpy="0 0 0" />
    <parent
      link="FR_footmotor" />
    <child
      link="FR_foot" />
    <axis
      xyz="0 1 0" />
    <!-- <dynamics friction="1.0" /> -->
    <limit
      lower="-9999"
      upper="9999"
      effort="56"
      velocity="47" />
  </joint>
  <link
    name="RL_hip">
    <inertial>
      <origin
        xyz="0.016427 0.0038854 -2.206E-06"
        rpy="0 0 0" />
      <mass
        value="3.1" />
      <inertia
        ixx="0.00586263"
        ixy="-0.00040875"
        ixz="-0.00003064"
        iyy="0.00941998"
        iyz="0.00000024"
        izz="0.00823554" />
    </inertial>
    <visual>
      <origin
        xyz="0 0 0"
        rpy="0 0 0" />
      <geometry>
        <mesh
          filename="../meshes/RL_hip.STL" />
      </geometry>
      <material
        name="">
        <color
          rgba="0.75294 0.75294 0.75294 1" />
      </material>
    </visual>
    <!--空碰撞-->
  </link>
  <joint
    name="RL_hip_joint"
    type="revolute">
    <origin
      xyz="-0.42896 0.056588 0.00014972"
      rpy="0 0 0" />
    <parent
      link="base" />
    <child
      link="RL_hip" />
    <axis
      xyz="1 0 0" />
    <!-- <dynamics damping="0.05" friction="0.01" /> -->
    <limit
      lower="-1.51"
      upper="0.8"
      effort="150"
      velocity="12" />
  </joint>
  <link
    name="RL_thigh">
    <inertial>
      <origin
        xyz="0.0055271 0.00015362 -0.092992"
        rpy="0 0 0" />
      <mass
        value="4.1" />
      <inertia
        ixx="0.07200998"
        ixy="0.00045575"
        ixz="-0.00288100"
        iyy="0.06900584"
        iyz="-0.00892980"
        izz="0.01142712" />
    </inertial>
    <visual>
      <origin
        xyz="0 0 0"
        rpy="0 0 0" />
      <geometry>
        <mesh
          filename="../meshes/RL_thigh.STL" />
      </geometry>
      <material
        name="">
        <color
          rgba="0.75294 0.75294 0.75294 1" />
      </material>
    </visual>
    <!--空碰撞-->
  </link>
  <joint
    name="RL_thigh_joint"
    type="revolute">
    <origin
      xyz="0 0.1324 0"
      rpy="0 0 0" />
    <parent
      link="RL_hip" />
    <child
      link="RL_thigh" />
    <axis
      xyz="0 1 0" />
    <!-- <dynamics damping="0.05" friction="0.01" /> -->
    <limit
      lower="-2.6"
      upper="1.57"
      effort="150"
      velocity="12" />
  </joint>
  <link
    name="RL_calf">
    <inertial>
      <origin
        xyz="0.00040423 0.0007071 -0.14806"
        rpy="0 0 0" />
      <mass
        value="0.8" />
      <inertia
        ixx="0.01454129"
        ixy="-0.00000055"
        ixz="0.00006627"
        iyy="0.01478402"
        iyz="-0.00009312"
        izz="0.00049821" />
    </inertial>
    <visual>
      <origin
        xyz="0 0 0"
        rpy="0 0 0" />
      <geometry>
        <mesh
          filename="../meshes/RL_calf.STL" />
      </geometry>
      <material
        name="">
        <color
          rgba="0.75294 0.75294 0.75294 1" />
      </material>
    </visual>
      <collision>
        <origin xyz="0 -0.0 -0.170" rpy="0 0 0" />
        <geometry>
          <box size="0.05 0.045 0.390" />
        </geometry>
      </collision>
  </link>
  <joint
    name="RL_calf_joint"
    type="revolute">
    <origin
      xyz="0 0.0241 -0.33"
      rpy="0 0 0" />
    <parent
      link="RL_thigh" />
    <child
      link="RL_calf" />
    <axis
      xyz="0 1 0" />
    <!-- <dynamics damping="0.05" friction="0.01" /> -->
    <limit
      lower="0.5"
      upper="2.47"
      effort="150"
      velocity="8" />
  </joint>
  <link
    name="RL_footmotor">
    <inertial>
      <origin
        xyz="-3.0956E-07 0.037959 0.0077964"
        rpy="0 0 0" />
      <mass
        value="1" />
      <inertia
        ixx="0.00122551"
        ixy="0.00000001"
        ixz="0.00000089"
        iyy="0.00121122"
        iyz="-0.00011534"
        izz="0.00111829" />
    </inertial>
    <visual>
      <origin
        xyz="0 0 0"
        rpy="0 0 0" />
      <geometry>
        <mesh
          filename="../meshes/RL_footmotor.STL" />
      </geometry>
      <material
        name="">
        <color
          rgba="0.75294 0.75294 0.75294 1" />
      </material>
    </visual>
    <!--空碰撞-->
  </link>
  <joint
    name="RL_footmotor_fixed"
    type="fixed">
    <origin
      xyz="0 -0.019084 -0.3352"
      rpy="0 0 0" />
    <parent
      link="RL_calf" />
    <child
      link="RL_footmotor" />
    <axis
      xyz="0 0 0" />
  </joint>
  <link
    name="RL_foot">
    <inertial>
      <origin
        xyz="5.5207E-08 -0.00082201 1.8119E-08"
        rpy="0 0 0" />
      <mass
        value="0.8" />
      <inertia
        ixx="0.00322619"
        ixy="0.0"
        ixz="0.0"
        iyy="0.00620216"
        iyz="0.0"
        izz="0.00322620" />
    </inertial>
    <visual>
      <origin
        xyz="0 0 0"
        rpy="0 0 0" />
      <geometry>
        <mesh
          filename="../meshes/RL_foot.STL" />
      </geometry>
      <material
        name="">
        <color
          rgba="0.75294 0.75294 0.75294 1" />
      </material>
    </visual>
      <collision>
        <origin xyz="0 0.0 0" rpy="1.5707963267948966 0 0" />
        <geometry>
          <cylinder length="0.040" radius="0.105" />
        </geometry>
      </collision>
  </link>
  <joint
    name="RL_foot_joint"
    type="revolute">
    <origin
      xyz="0 0.067334 0.0052008"
      rpy="0 0 0" />
    <parent
      link="RL_footmotor" />
    <child
      link="RL_foot" />
    <axis
      xyz="0 1 0" />
    <!-- <dynamics friction="1.0" /> -->
    <limit
      lower="-9999"
      upper="9999"
      effort="56"
      velocity="47" />
  </joint>
  <link
    name="RR_hip">
    <inertial>
      <origin
        xyz="0.016427 -0.0038854 2.2056E-06"
        rpy="0 0 0" />
      <mass
        value="3.1" />
      <inertia
        ixx="0.00586263"
        ixy="0.00040875"
        ixz="0.00003064"
        iyy="0.00941998"
        iyz="0.00000024"
        izz="0.00823554" />
    </inertial>
    <visual>
      <origin
        xyz="0 0 0"
        rpy="0 0 0" />
      <geometry>
        <mesh
          filename="../meshes/RR_hip.STL" />
      </geometry>
      <material
        name="">
        <color
          rgba="0.75294 0.75294 0.75294 1" />
      </material>
    </visual>
    <!--空碰撞-->
  </link>
  <joint
    name="RR_hip_joint"
    type="revolute">
    <origin
      xyz="-0.42896 -0.11341 0.00014972"
      rpy="0 0 0" />
    <parent
      link="base" />
    <child
      link="RR_hip" />
    <axis
      xyz="1 0 0" />
    <!-- <dynamics damping="0.05" friction="0.01" /> -->
    <limit
      lower="-1.58"
      upper="0.79"
      effort="150"
      velocity="12" />
  </joint>
  <link
    name="RR_thigh">
    <inertial>
      <origin
        xyz="0.0051952 -0.00015428 -0.092972"
        rpy="0 0 0" />
      <mass
        value="4.1" />
      <inertia
        ixx="0.07198856"
        ixy="-0.00056758"
        ixz="-0.00301968"
        iyy="0.06899899"
        iyz="0.00892753"
        izz="0.01143578" />
    </inertial>
    <visual>
      <origin
        xyz="0 0 0"
        rpy="0 0 0" />
      <geometry>
        <mesh
          filename="../meshes/RR_thigh.STL" />
      </geometry>
      <material
        name="">
        <color
          rgba="0.75294 0.75294 0.75294 1" />
      </material>
    </visual>
    <!--空碰撞-->
  </link>
  <joint
    name="RR_thigh_joint"
    type="revolute">
    <origin
      xyz="0 -0.1324 0"
      rpy="0 0 0" />
    <parent
      link="RR_hip" />
    <child
      link="RR_thigh" />
    <axis
      xyz="0 1 0" />
    <!-- <dynamics damping="0.05" friction="0.01" /> -->
    <limit
      lower="-2.6"
      upper="1.58"
      effort="150"
      velocity="12" />
  </joint>
  <link
    name="RR_calf">
    <inertial>
      <origin
        xyz="0.00045097 0.010664 -0.14659"
        rpy="0 0 0" />
      <mass
        value="0.8" />
      <inertia
        ixx="0.01454306"
        ixy="0.00000018"
        ixz="0.00008077"
        iyy="0.01488481"
        iyz="0.00016534"
        izz="0.00041348" />
    </inertial>
    <visual>
      <origin
        xyz="0 0 0"
        rpy="0 0 0" />
      <geometry>
        <mesh
          filename="../meshes/RR_calf.STL" />
      </geometry>
      <material
        name="">
        <color
          rgba="0.75294 0.75294 0.75294 1" />
      </material>
    </visual>
      <collision>
        <origin xyz="0 0.0 -0.170" rpy="0 0 0" />
        <geometry>
          <box size="0.05 0.045 0.390" />
        </geometry>
      </collision>
  </link>
  <joint
    name="RR_calf_joint"
    type="revolute">
    <origin
      xyz="0 -0.0241 -0.33"
      rpy="0 0 0" />
    <parent
      link="RR_thigh" />
    <child
      link="RR_calf" />
    <axis
      xyz="0 1 0" />
    <!-- <dynamics damping="0.05" friction="0.01" /> -->
    <limit
      lower="0.45"
      upper="2.4"
      effort="150"
      velocity="8" />
  </joint>
  <link
    name="RR_footmotor">
    <inertial>
      <origin
        xyz="3.0956E-07 -0.037959 0.0077964"
        rpy="0 0 0" />
      <mass
        value="1" />
      <inertia
        ixx="0.00122551"
        ixy="0.00000001"
        ixz="-0.00000089"
        iyy="0.00121122"
        iyz="0.00011534"
        izz="0.00111829" />
    </inertial>
    <visual>
      <origin
        xyz="0 0 0"
        rpy="0 0 0" />
      <geometry>
        <mesh
          filename="../meshes/RR_footmotor.STL" />
      </geometry>
      <material
        name="">
        <color
          rgba="0.75294 0.75294 0.75294 1" />
      </material>
    </visual>
    <!--空碰撞-->
  </link>
  <joint
    name="RR_footmotor_fixed"
    type="fixed">
    <origin
      xyz="0 0.019084 -0.3352"
      rpy="0 0 0" />
    <parent
      link="RR_calf" />
    <child
      link="RR_footmotor" />
    <axis
      xyz="0 0 0" />
  </joint>
  <link
    name="RR_foot">
    <inertial>
      <origin
        xyz="5.6617E-08 0.00082201 -1.3061E-08"
        rpy="0 0 0" />
      <mass
        value="0.8" />
      <inertia
        ixx="0.00322619"
        ixy="0.0"
        ixz="0.0"
        iyy="0.00620216"
        iyz="0.0"
        izz="0.00322620" />
    </inertial>
    <visual>
      <origin
        xyz="0 0 0"
        rpy="0 0 0" />
      <geometry>
        <mesh
          filename="../meshes/RR_foot.STL" />
      </geometry>
      <material
        name="">
        <color
          rgba="0.75294 0.75294 0.75294 1" />
      </material>
    </visual>
      <collision>
        <origin xyz="0 -0.0 0" rpy="1.5707963267948966 0 0" />
        <geometry>
          <cylinder length="0.040" radius="0.105" />
        </geometry>
      </collision>
  </link>
  <joint
    name="RR_foot_joint"
    type="revolute">
    <origin
      xyz="0 -0.067334 0.0052008"
      rpy="0 0 0" />
    <parent
      link="RR_footmotor" />
    <child
      link="RR_foot" />
    <axis
      xyz="0 1 0" />
    <!-- <dynamics friction="1.0" /> -->
    <limit
      lower="-9999"
      upper="9999"
      effort="56"
      velocity="47" />
  </joint>
</robot>
